<?xml version="1.0" encoding="utf-8"?>
<!-- This URDF was automatically created by SolidWorks to URDF Exporter! Originally created by Stephen Brawner (brawner@gmail.com) 
     Commit Version: 1.6.0-4-g7f85cfe  Build Version: 1.6.7995.38578
     For more information, please see http://wiki.ros.org/sw_urdf_exporter -->
<robot
  name="Mini Assembly R6 Assembly Type">
  <link
    name="base_link">
    <inertial>
      <origin
        xyz="-0.005147 5.9588E-09 0.034934"
        rpy="0 0 0" />
      <mass
        value="1.8278" />
      <inertia
        ixx="0.0020831"
        ixy="2.5979E-11"
        ixz="2.027E-14"
        iyy="0.0016842"
        iyz="3.8168E-14"
        izz="0.0032646" />
    </inertial>
    <visual>
      <origin
        xyz="0 0 0"
        rpy="0 0 0" />
      <geometry>
        <mesh
          filename="package://Mini Assembly R6 Assembly Type/meshes/base_link.STL" />
      </geometry>
      <material
        name="">
        <color
          rgba="0.75294 0.75294 0.75294 1" />
      </material>
    </visual>
    <collision>
      <origin
        xyz="0 0 0"
        rpy="0 0 0" />
      <geometry>
        <mesh
          filename="package://Mini Assembly R6 Assembly Type/meshes/base_link.STL" />
      </geometry>
    </collision>
  </link>
  <link
    name="Link 1 ">
    <inertial>
      <origin
        xyz="2.1653E-11 -9.0996E-11 2.7473E-10"
        rpy="0 0 0" />
      <mass
        value="0.28916" />
      <inertia
        ixx="0.00011541"
        ixy="1.4857E-13"
        ixz="7.1807E-13"
        iyy="0.00012866"
        iyz="-4.2388E-12"
        izz="0.00011494" />
    </inertial>
    <visual>
      <origin
        xyz="0 0 0"
        rpy="0 0 0" />
      <geometry>
        <mesh
          filename="package://Mini Assembly R6 Assembly Type/meshes/Link 1 .STL" />
      </geometry>
      <material
        name="">
        <color
          rgba="0.75294 0.75294 0.75294 1" />
      </material>
    </visual>
    <collision>
      <origin
        xyz="0 0 0"
        rpy="0 0 0" />
      <geometry>
        <mesh
          filename="package://Mini Assembly R6 Assembly Type/meshes/Link 1 .STL" />
      </geometry>
    </collision>
  </link>
  <joint
    name="J1"
    type="revolute">
    <origin
      xyz="0 0 0.075121"
      rpy="0 0 0" />
    <parent
      link="base_link" />
    <child
      link="Link 1 " />
    <axis
      xyz="0 0 1" />
    <limit
      lower="3.14"
      upper="-3.14"
      effort="10"
      velocity="50" />
  </joint>
</robot>