<?xml version="1.0" encoding="utf-8"?>
<!-- This URDF was automatically created by SolidWorks to URDF Exporter! Originally created by Stephen Brawner (brawner@gmail.com) 
     Commit Version: 1.6.0-4-g7f85cfe  Build Version: 1.6.7995.38578
     For more information, please see http://wiki.ros.org/sw_urdf_exporter -->
<robot
  name="Phase 2 ALL LINKS">
  <link
    name="base_link">
    <inertial>
      <origin
        xyz="-2.3158E-07 -0.0066564 0.035"
        rpy="0 0 0" />
      <mass
        value="1.3468" />
      <inertia
        ixx="0.001167"
        ixy="1.0458E-11"
        ixz="-1.3577E-14"
        iyy="0.001545"
        iyz="-3.1447E-14"
        izz="0.0023418" />
    </inertial>
    <visual>
      <origin
        xyz="0 0 0"
        rpy="0 0 0" />
      <geometry>
        <mesh
          filename="package://Phase 2 ALL LINKS/meshes/base_link.STL" />
      </geometry>
      <material
        name="">
        <color
          rgba="0.75294 0.75294 0.75294 1" />
      </material>
    </visual>
    <collision>
      <origin
        xyz="0 0 0"
        rpy="0 0 0" />
      <geometry>
        <mesh
          filename="package://Phase 2 ALL LINKS/meshes/base_link.STL" />
      </geometry>
    </collision>
  </link>
  <link
    name="Link 1 -  Purple">
    <inertial>
      <origin
        xyz="0.00046301 2.9701E-08 0.073559"
        rpy="0 0 0" />
      <mass
        value="0.3271" />
      <inertia
        ixx="0.00012213"
        ixy="-1.5392E-11"
        ixz="4.8687E-09"
        iyy="0.00013427"
        iyz="-6.6384E-11"
        izz="0.00011641" />
    </inertial>
    <visual>
      <origin
        xyz="0 0 0"
        rpy="0 0 0" />
      <geometry>
        <mesh
          filename="package://Phase 2 ALL LINKS/meshes/Link 1 -  Purple.STL" />
      </geometry>
      <material
        name="">
        <color
          rgba="0.75294 0.75294 0.75294 1" />
      </material>
    </visual>
    <collision>
      <origin
        xyz="0 0 0"
        rpy="0 0 0" />
      <geometry>
        <mesh
          filename="package://Phase 2 ALL LINKS/meshes/Link 1 -  Purple.STL" />
      </geometry>
    </collision>
  </link>
  <joint
    name="J1"
    type="revolute">
    <origin
      xyz="0 0 0.0025"
      rpy="0 0 0" />
    <parent
      link="base_link" />
    <child
      link="Link 1 -  Purple" />
    <axis
      xyz="0 0 1" />
    <limit
      lower="3.14"
      upper="-3.14"
      effort="10"
      velocity="100" />
  </joint>
  <link
    name="Link 2 - Orange ">
    <inertial>
      <origin
        xyz="1.5151E-05 0.11766 2.5215E-08"
        rpy="0 0 0" />
      <mass
        value="0.52509" />
      <inertia
        ixx="0.00097461"
        ixy="-8.5659E-09"
        ixz="-3.1016E-11"
        iyy="0.00010143"
        iyz="3.7769E-11"
        izz="0.0010037" />
    </inertial>
    <visual>
      <origin
        xyz="0 0 0"
        rpy="0 0 0" />
      <geometry>
        <mesh
          filename="package://Phase 2 ALL LINKS/meshes/Link 2 - Orange .STL" />
      </geometry>
      <material
        name="">
        <color
          rgba="0.75294 0.75294 0.75294 1" />
      </material>
    </visual>
    <collision>
      <origin
        xyz="0 0 0"
        rpy="0 0 0" />
      <geometry>
        <mesh
          filename="package://Phase 2 ALL LINKS/meshes/Link 2 - Orange .STL" />
      </geometry>
    </collision>
  </link>
  <joint
    name="J2"
    type="revolute">
    <origin
      xyz="0.0013777 0 0.133"
      rpy="1.5708 0 0" />
    <parent
      link="Link 1 -  Purple" />
    <child
      link="Link 2 - Orange " />
    <axis
      xyz="0 0 -1" />
    <limit
      lower="3.14"
      upper="-3.14"
      effort="10"
      velocity="100" />
  </joint>
  <link
    name="Link 3 - Pink ">
    <inertial>
      <origin
        xyz="0.0065159 0.17422 4.1508E-09"
        rpy="0 0 0" />
      <mass
        value="0.90189" />
      <inertia
        ixx="0.0011587"
        ixy="-1.3066E-05"
        ixz="1.2482E-13"
        iyy="0.00027951"
        iyz="2.4698E-12"
        izz="0.0012549" />
    </inertial>
    <visual>
      <origin
        xyz="0 0 0"
        rpy="0 0 0" />
      <geometry>
        <mesh
          filename="package://Phase 2 ALL LINKS/meshes/Link 3 - Pink .STL" />
      </geometry>
      <material
        name="">
        <color
          rgba="0.75294 0.75294 0.75294 1" />
      </material>
    </visual>
    <collision>
      <origin
        xyz="0 0 0"
        rpy="0 0 0" />
      <geometry>
        <mesh
          filename="package://Phase 2 ALL LINKS/meshes/Link 3 - Pink .STL" />
      </geometry>
    </collision>
  </link>
  <joint
    name="J3"
    type="revolute">
    <origin
      xyz="0.00014239 0.26004 0"
      rpy="0 0 -1.5708" />
    <parent
      link="Link 2 - Orange " />
    <child
      link="Link 3 - Pink " />
    <axis
      xyz="0 0 -1" />
    <limit
      lower="3.14"
      upper="-3.14"
      effort="10"
      velocity="100" />
  </joint>
  <link
    name="Link 4 - Green">
    <inertial>
      <origin
        xyz="0.027427 -0.0072642 -0.0088925"
        rpy="0 0 0" />
      <mass
        value="0.42106" />
      <inertia
        ixx="0.00012527"
        ixy="1.6054E-05"
        ixz="-1.8828E-05"
        iyy="0.0002039"
        iyz="9.122E-06"
        izz="0.00021331" />
    </inertial>
    <visual>
      <origin
        xyz="0 0 0"
        rpy="0 0 0" />
      <geometry>
        <mesh
          filename="package://Phase 2 ALL LINKS/meshes/Link 4 - Green.STL" />
      </geometry>
      <material
        name="">
        <color
          rgba="0.75294 0.75294 0.75294 1" />
      </material>
    </visual>
    <collision>
      <origin
        xyz="0 0 0"
        rpy="0 0 0" />
      <geometry>
        <mesh
          filename="package://Phase 2 ALL LINKS/meshes/Link 4 - Green.STL" />
      </geometry>
    </collision>
  </link>
  <joint
    name="J4"
    type="revolute">
    <origin
      xyz="0 0.33608 0"
      rpy="-1.5708 0 0" />
    <parent
      link="Link 3 - Pink " />
    <child
      link="Link 4 - Green" />
    <axis
      xyz="0 0 -1" />
    <limit
      lower="3.14"
      upper="-3.14"
      effort="10"
      velocity="100" />
  </joint>
  <link
    name="Link 5 - Yellow ">
    <inertial>
      <origin
        xyz="0.0080411 0.00098636 0.0043369"
        rpy="0 0 0" />
      <mass
        value="0.083993" />
      <inertia
        ixx="1.199E-05"
        ixy="6.5403E-08"
        ixz="4.8836E-08"
        iyy="2.022E-05"
        iyz="4.7655E-09"
        izz="2.1062E-05" />
    </inertial>
    <visual>
      <origin
        xyz="0 0 0"
        rpy="0 0 0" />
      <geometry>
        <mesh
          filename="package://Phase 2 ALL LINKS/meshes/Link 5 - Yellow .STL" />
      </geometry>
      <material
        name="">
        <color
          rgba="0.75294 0.75294 0.75294 1" />
      </material>
    </visual>
    <collision>
      <origin
        xyz="0 0 0"
        rpy="0 0 0" />
      <geometry>
        <mesh
          filename="package://Phase 2 ALL LINKS/meshes/Link 5 - Yellow .STL" />
      </geometry>
    </collision>
  </link>
  <joint
    name="J5"
    type="revolute">
    <origin
      xyz="0 0 0"
      rpy="1.5708 0 -1.5708" />
    <parent
      link="Link 4 - Green" />
    <child
      link="Link 5 - Yellow " />
    <axis
      xyz="0 0 -1" />
    <limit
      lower="3.14"
      upper="-3.14"
      effort="10"
      velocity="100" />
  </joint>
  <link
    name="Link 6 - Magenta">
    <inertial>
      <origin
        xyz="0.034393 0.00061009 0.078958"
        rpy="0 0 0" />
      <mass
        value="0.97068" />
      <inertia
        ixx="0.00029072"
        ixy="-8.9988E-08"
        ixz="6.3805E-05"
        iyy="0.00057947"
        iyz="3.91E-08"
        izz="0.00052921" />
    </inertial>
    <visual>
      <origin
        xyz="0 0 0"
        rpy="0 0 0" />
      <geometry>
        <mesh
          filename="package://Phase 2 ALL LINKS/meshes/Link 6 - Magenta.STL" />
      </geometry>
      <material
        name="">
        <color
          rgba="0.75294 0.75294 0.75294 1" />
      </material>
    </visual>
    <collision>
      <origin
        xyz="0 0 0"
        rpy="0 0 0" />
      <geometry>
        <mesh
          filename="package://Phase 2 ALL LINKS/meshes/Link 6 - Magenta.STL" />
      </geometry>
    </collision>
  </link>
  <joint
    name="J6"
    type="revolute">
    <origin
      xyz="0 0 0"
      rpy="-1.5708 1.5708 0" />
    <parent
      link="Link 5 - Yellow " />
    <child
      link="Link 6 - Magenta" />
    <axis
      xyz="0 0 -1" />
    <limit
      lower="3.14"
      upper="-3.14"
      effort="10"
      velocity="100" />
  </joint>
</robot>